Workbook
Name bps_dish: Sheet1!$M$23:$Q$28
Name bps_fab_en: Sheet1!$M$16:$Q$21
Name bps_liquid: Sheet1!$M$9:$Q$14
Name bps_powder: Sheet1!$M$2:$Q$7
Name cont_dish: Sheet1!$G$23:$K$28
Name cont_fab_en: Sheet1!$G$16:$K$21
Name cont_liquid: Sheet1!$G$9:$K$14
Name cont_powder: Sheet1!$G$2:$K$7
Name growth_pct_dish: Sheet1!$S$23:$W$28
Name growth_pct_fab_en: Sheet1!$S$16:$W$21
Name growth_pct_liquid: Sheet1!$S$9:$W$14
Name growth_pct_powder: Sheet1!$S$2:$W$7

Sheet Sheet1
A2: Total TH | B2: Channel | C2: Price | D2: Region | E2: Packsize | G2: Total TH | H2: Channel | I2: Price | J2: Region | K2: Packsize | M2: Total | N2: Channel | O2: Price | P2: Region | Q2: Packsize | S2: Total | T2: Channel | U2: Price | V2: Region | W2: Packsize
A3: Powder | B3: SH CHAIN | C3: Tier1 | D3: GBKK | E3: S | G3: 0.51787842 | H3: 0.11520074 | I3: 0.22257892 | J3: 0.10756976 | K3: 0.042699995 | M3: -44 bps | N3: -164 bps | O3: -121 bps | P3: -45 bps | Q3: -87 bps | S3: -0.033769568 | T3: -0.14699333 | U3: -0.07561586 | V3: -0.064430566 | W3: -0.19016239
B4: SH Online | C4: Tier2 | D4: CENTRAL | E4: M | H4: 0.006369998 | I4: 0.044540326 | J4: 0.13346584 | K4: 0.086627068 | N4: 14 bps | O4: -68 bps | P4: 64 bps | Q4: -109 bps | T4: 0.23859021 | U4: -0.15523999 | V4: 0.023838855 | W4: -0.13455768
B5: OT | C5: Tier3 | D5: NORTH | E5: L | H5: 0.20885832 | I5: 0.24245091 | J5: 0.080127092 | K5: 0.148535 | N5: 111 bps | O5: 92 bps | P5: 35 bps | Q5: 4 bps | T5: 0.029339501 | U5: 0.01304944 | V5: 0.0196116 | W5: -0.023175949
B6: LMT | C6: Tier4 | D6: NORTHEAST | E6: XL | H6: 0.11460796 | I6: 0.008308268 | J6: 0.14590385 | K6: 0.19869052 | N6: 172 bps | O6: 52 bps | P6: -65 bps | Q6: 195 bps | T6: 0.14650287 | U6: 1.6469855 | V6: -0.067040067 | W6: 0.08063572
B7: CVS | D7: SOUTH | E7: XXL | H7: 0.072841401 | J7: 0.050811878 | K7: 0.041325837 | N7: -177 bps | P7: -34 bps | Q7: -47 bps | T7: -0.21600319 | V7: -0.087234582 | W7: -0.12505055
A9: Total TH | B9: Channel | C9: Price | D9: Region | E9: Packsize | G9: Total TH | H9: Channel | I9: Price | J9: Region | K9: Packsize | M9: Total | N9: Channel | O9: Price | P9: Region | Q9: Packsize | S9: Total | T9: Channel | U9: Price | V9: Region | W9: Packsize
A10: LIQUID | B10: SH CHAIN | C10: Tier1 | D10: GBKK | E10: S | G10: 0.39367265 | H10: 0.13971965 | I10: 0.02 | J10: 0.14497907 | K10: 0.013224554 | M10: 242 bps | N10: -85 bps | O10: 139 bps | P10: 117 bps | Q10: -59 bps | S10: 0.27503667 | T10: 0.18085306 | U10: 2.0837462 | V10: 0.3626972 | W10: -0.1351163
B11: SH Online | C11: Tier2 | D11: CENTRAL | E11: M | H11: 0.0074350914 | I11: 0.083092678 | J11: 0.10499789 | K11: 0.017087706 | N11: 8 bps | O11: -237 bps | P11: 35 bps | Q11: -49 bps | T11: 0.40367161 | U11: -0.04279823 | V11: 0.29591555 | W11: -0.028308905
B12: OT | C12: Tier3 | D12: NORTH | E12: L | H12: 0.044699993 | I12: 0.29 | J12: 0.042425781 | K12: 0.18701734 | N12: -17 bps | O12: 231 bps | P12: 24 bps | Q12: 189 bps | T12: 0.20656131 | U12: 0.34314698 | V12: 0.32767862 | W12: 0.39360677
B13: LMT | C13: Tier4 | D13: NORTHEAST | E13: XL | H13: 0.089555564 | I13: 0 | J13: 0.065997762 | K13: 0.17578255 | N13: 71 bps | O13: 0 bps | P13: 40 bps | Q13: 162 bps | T13: 0.36059292 | U13: -1 | V13: 0.33287926 | W13: 0.38031717
B14: CVS | D14: SOUTH | E14: XXL | H14: 0.11226235 | J14: 0.035272138 | K14: 0.00056049231 | N14: 266 bps | P14: 27 bps | Q14: 0 bps | T14: 0.64194712 | V14: 0.35796565 | W14: 0.28669916
A16: Total TH | B16: Channel | C16: Price | D16: Region | E16: Packsize | G16: Total TH | H16: Channel | I16: Price | J16: Region | K16: Packsize | M16: Total | N16: Channel | O16: Price | P16: Region | Q16: Packsize | S16: Total | T16: Channel | U16: Price | V16: Region | W16: Packsize
A17: FAB ENH | B17: SH CHAIN | C17: Tier1 | D17: GBKK | E17: S | G17: 0.14301828 | H17: 0.049774059 | J17: 0.046661038 | K17: 0.015680977 | M17: 47 bps | N17: 79 bps | O17: -173 bps | P17: 14 bps | Q17: -64 bps | S17: 0.12792495 | T17: 0.29863891 | U17: -0.85537963 | V17: 0.12460977 | W17: -0.22649364
B18: SH Online | C18: Tier2 | D18: CENTRAL | E18: M | I18: 0.123 | J18: 0.04220721 | N18: 5 bps | O18: 275 bps | P18: 31 bps | Q18: -52 bps | T18: 0.4001739 | U18: 0.42433856 | V18: 0.17862989 | W18: -0.79275633
B19: OT | C19: Tier3 | D19: NORTH | E19: L | H19: 0.024759749 | I19: 0.02 | J19: 0.015791584 | K19: 0.08 | N19: -18 bps | O19: -41 bps | P19: -7 bps | Q19: 3 bps | T19: 0.018240481 | U19: -0.085769451 | V19: 0.0451762 | W19: 0.09523052
B20: LMT | C20: Tier4 | D20: NORTHEAST | E20: XL | H20: 0.0285 | J20: 0.025993493 | K20: 0.047 | N20: 32 bps | O20: -14 bps | P20: 4 bps | Q20: 163 bps | T20: 0.22587845 | U20: -0.38776861 | V20: 0.10927053 | W20: 0.65422605
B21: CVS | D21: SOUTH | E21: XXL | H21: 0.04 | J21: 0.012364959 | N21: -52 bps | P21: 4 bps | Q21: -2 bps | T21: -0.042630634 | V21: 0.12876173 | W21: -0.053766533
A23: Total TH | B23: Channel | C23: Price | D23: Region | E23: Packsize | G23: Total TH | H23: Channel | I23: Price | J23: Region | K23: Packsize | M23: Total | N23: Channel | O23: Price | P23: Region | Q23: Packsize | S23: Total | T23: Channel | U23: Price | V23: Region | W23: Packsize
A24: DW | B24: SH CHAIN | C24: Tier1 | D24: GBKK | E24: S | G24: 0.62101444 | H24: 0.16633831 | I24: 0.52984994 | J24: 0.15172307 | K24: 0.20293123 | M24: -137 bps | N24: -202 bps | O24: -270 bps | P24: -70 bps | Q24: -182 bps | S24: 0.034473772 | T24: -0.057147908 | U24: 0.0060154723 | V24: 0.010681762 | W24: -0.029576374
B25: SH Online | C25: Tier2 | D25: CENTRAL | E25: M | H25: 0.014610818 | I25: 0.019610653 | J25: 0.15008274 | K25: 0.1273448 | N25: 39 bps | O25: 132 bps | P25: -54 bps | Q25: 74 bps | T25: 0.44832951 | U25: 2.2232613 | V25: 0.020888919 | W25: 0.12213868
B26: OT | C26: Tier3 | D26: NORTH | E26: L | H26: 0.18836548 | I26: 0.071553844 | J26: 0.071203685 | K26: 0.11651568 | N26: -77 bps | O26: 1 bps | P26: -28 bps | Q26: -254 bps | T26: 0.015573845 | U26: 0.059219501 | V26: 0.017567677 | W26: -0.13167219
B27: LMT | C27: Tier4 | D27: NORTHEAST | E27: XL | H27: 0.13992112 | I27: 0 | J27: 0.17630647 | K27: 0.17422272 | N27: 260 bps | P27: 34 bps | Q27: 225 bps | T27: 0.2989023 | V27: 0.078040867 | W27: 0.21379922
B28: CVS | D28: SOUTH | E28: XXL | H28: 0.1117787 | J28: 0.071698466 | K28: 0 | N28: -157 bps | P28: -20 bps | T28: -0.073231741 | V28: 0.029114997

Sheet Decomposition
A1: POWDER — Decomposition source (raw shares)
A2: Dimension | B2: Block | C2: Share% | D2: Label | E2: BPS | F2: Growth%
A3: =Sheet1!G2 -> Total TH | B3: 1 | C3: =IFERROR(N(Sheet1!G3)*100,0) -> 51.787842 | D3: =IF(TRIM(Sheet1!A3)="","",Sheet1!A3) -> Powder | E3: =IFERROR(IF(TRIM(Sheet1!M3)="","",VALUE(SUBSTITUTE(SUBSTITUTE(Sheet1!M3," bps",""),",",""))),"") -> -44 | F3: =IFERROR(IF(Sheet1!S3="","",N(Sheet1!S3)*100),"") -> -3.3769568
A4: =Sheet1!G2 -> Total TH | B4: 2 | C4: =IFERROR(N(Sheet1!G4)*100,0) -> 0 | D4: =IF(TRIM(Sheet1!A4)="","",Sheet1!A4) | E4: =IFERROR(IF(TRIM(Sheet1!M4)="","",VALUE(SUBSTITUTE(SUBSTITUTE(Sheet1!M4," bps",""),",",""))),"") | F4: =IFERROR(IF(Sheet1!S4="","",N(Sheet1!S4)*100),"")
A5: =Sheet1!G2 -> Total TH | B5: 3 | C5: =IFERROR(N(Sheet1!G5)*100,0) -> 0 | D5: =IF(TRIM(Sheet1!A5)="","",Sheet1!A5) | E5: =IFERROR(IF(TRIM(Sheet1!M5)="","",VALUE(SUBSTITUTE(SUBSTITUTE(Sheet1!M5," bps",""),",",""))),"") | F5: =IFERROR(IF(Sheet1!S5="","",N(Sheet1!S5)*100),"")
A6: =Sheet1!G2 -> Total TH | B6: 4 | C6: =IFERROR(N(Sheet1!G6)*100,0) -> 0 | D6: =IF(TRIM(Sheet1!A6)="","",Sheet1!A6) | E6: =IFERROR(IF(TRIM(Sheet1!M6)="","",VALUE(SUBSTITUTE(SUBSTITUTE(Sheet1!M6," bps",""),",",""))),"") | F6: =IFERROR(IF(Sheet1!S6="","",N(Sheet1!S6)*100),"")
A7: =Sheet1!G2 -> Total TH | B7: 5 | C7: =IFERROR(N(Sheet1!G7)*100,0) -> 0 | D7: =IF(TRIM(Sheet1!A7)="","",Sheet1!A7) | E7: =IFERROR(IF(TRIM(Sheet1!M7)="","",VALUE(SUBSTITUTE(SUBSTITUTE(Sheet1!M7," bps",""),",",""))),"") | F7: =IFERROR(IF(Sheet1!S7="","",N(Sheet1!S7)*100),"")
A8: =Sheet1!H2 -> Channel | B8: 1 | C8: =IFERROR(N(Sheet1!H3)*100,0) -> 11.520074 | D8: =IF(TRIM(Sheet1!B3)="","",Sheet1!B3) -> SH CHAIN | E8: =IFERROR(IF(TRIM(Sheet1!N3)="","",VALUE(SUBSTITUTE(SUBSTITUTE(Sheet1!N3," bps",""),",",""))),"") -> -164 | F8: =IFERROR(IF(Sheet1!T3="","",N(Sheet1!T3)*100),"") -> -14.699333
A9: =Sheet1!H2 -> Channel | B9: 2 | C9: =IFERROR(N(Sheet1!H4)*100,0) -> 0.6369998 | D9: =IF(TRIM(Sheet1!B4)="","",Sheet1!B4) -> SH Online | E9: =IFERROR(IF(TRIM(Sheet1!N4)="","",VALUE(SUBSTITUTE(SUBSTITUTE(Sheet1!N4," bps",""),",",""))),"") -> 14 | F9: =IFERROR(IF(Sheet1!T4="","",N(Sheet1!T4)*100),"") -> 23.859021
A10: =Sheet1!H2 -> Channel | B10: 3 | C10: =IFERROR(N(Sheet1!H5)*100,0) -> 20.885832 | D10: =IF(TRIM(Sheet1!B5)="","",Sheet1!B5) -> OT | E10: =IFERROR(IF(TRIM(Sheet1!N5)="","",VALUE(SUBSTITUTE(SUBSTITUTE(Sheet1!N5," bps",""),",",""))),"") -> 111 | F10: =IFERROR(IF(Sheet1!T5="","",N(Sheet1!T5)*100),"") -> 2.9339501
A11: =Sheet1!H2 -> Channel | B11: 4 | C11: =IFERROR(N(Sheet1!H6)*100,0) -> 11.460796 | D11: =IF(TRIM(Sheet1!B6)="","",Sheet1!B6) -> LMT | E11: =IFERROR(IF(TRIM(Sheet1!N6)="","",VALUE(SUBSTITUTE(SUBSTITUTE(Sheet1!N6," bps",""),",",""))),"") -> 172 | F11: =IFERROR(IF(Sheet1!T6="","",N(Sheet1!T6)*100),"") -> 14.650287
A12: =Sheet1!H2 -> Channel | B12: 5 | C12: =IFERROR(N(Sheet1!H7)*100,0) -> 7.2841401 | D12: =IF(TRIM(Sheet1!B7)="","",Sheet1!B7) -> CVS | E12: =IFERROR(IF(TRIM(Sheet1!N7)="","",VALUE(SUBSTITUTE(SUBSTITUTE(Sheet1!N7," bps",""),",",""))),"") -> -177 | F12: =IFERROR(IF(Sheet1!T7="","",N(Sheet1!T7)*100),"") -> -21.600319
A13: =Sheet1!I2 -> Price | B13: 1 | C13: =IFERROR(N(Sheet1!I3)*100,0) -> 22.257892 | D13: =IF(TRIM(Sheet1!C3)="","",Sheet1!C3) -> Tier1 | E13: =IFERROR(IF(TRIM(Sheet1!O3)="","",VALUE(SUBSTITUTE(SUBSTITUTE(Sheet1!O3," bps",""),",",""))),"") -> -121 | F13: =IFERROR(IF(Sheet1!U3="","",N(Sheet1!U3)*100),"") -> -7.561586
A14: =Sheet1!I2 -> Price | B14: 2 | C14: =IFERROR(N(Sheet1!I4)*100,0) -> 4.4540326 | D14: =IF(TRIM(Sheet1!C4)="","",Sheet1!C4) -> Tier2 | E14: =IFERROR(IF(TRIM(Sheet1!O4)="","",VALUE(SUBSTITUTE(SUBSTITUTE(Sheet1!O4," bps",""),",",""))),"") -> -68 | F14: =IFERROR(IF(Sheet1!U4="","",N(Sheet1!U4)*100),"") -> -15.523999
A15: =Sheet1!I2 -> Price | B15: 3 | C15: =IFERROR(N(Sheet1!I5)*100,0) -> 24.245091 | D15: =IF(TRIM(Sheet1!C5)="","",Sheet1!C5) -> Tier3 | E15: =IFERROR(IF(TRIM(Sheet1!O5)="","",VALUE(SUBSTITUTE(SUBSTITUTE(Sheet1!O5," bps",""),",",""))),"") -> 92 | F15: =IFERROR(IF(Sheet1!U5="","",N(Sheet1!U5)*100),"") -> 1.304944
A16: =Sheet1!I2 -> Price | B16: 4 | C16: =IFERROR(N(Sheet1!I6)*100,0) -> 0.8308268 | D16: =IF(TRIM(Sheet1!C6)="","",Sheet1!C6) -> Tier4 | E16: =IFERROR(IF(TRIM(Sheet1!O6)="","",VALUE(SUBSTITUTE(SUBSTITUTE(Sheet1!O6," bps",""),",",""))),"") -> 52 | F16: =IFERROR(IF(Sheet1!U6="","",N(Sheet1!U6)*100),"") -> 164.69855
A17: =Sheet1!I2 -> Price | B17: 5 | C17: =IFERROR(N(Sheet1!I7)*100,0) -> 0 | D17: =IF(TRIM(Sheet1!C7)="","",Sheet1!C7) | E17: =IFERROR(IF(TRIM(Sheet1!O7)="","",VALUE(SUBSTITUTE(SUBSTITUTE(Sheet1!O7," bps",""),",",""))),"") | F17: =IFERROR(IF(Sheet1!U7="","",N(Sheet1!U7)*100),"")
A18: =Sheet1!J2 -> Region | B18: 1 | C18: =IFERROR(N(Sheet1!J3)*100,0) -> 10.756976 | D18: =IF(TRIM(Sheet1!D3)="","",Sheet1!D3) -> GBKK | E18: =IFERROR(IF(TRIM(Sheet1!P3)="","",VALUE(SUBSTITUTE(SUBSTITUTE(Sheet1!P3," bps",""),",",""))),"") -> -45 | F18: =IFERROR(IF(Sheet1!V3="","",N(Sheet1!V3)*100),"") -> -6.4430566
A19: =Sheet1!J2 -> Region | B19: 2 | C19: =IFERROR(N(Sheet1!J4)*100,0) -> 13.346584 | D19: =IF(TRIM(Sheet1!D4)="","",Sheet1!D4) -> CENTRAL | E19: =IFERROR(IF(TRIM(Sheet1!P4)="","",VALUE(SUBSTITUTE(SUBSTITUTE(Sheet1!P4," bps",""),",",""))),"") -> 64 | F19: =IFERROR(IF(Sheet1!V4="","",N(Sheet1!V4)*100),"") -> 2.3838855
A20: =Sheet1!J2 -> Region | B20: 3 | C20: =IFERROR(N(Sheet1!J5)*100,0) -> 8.0127092 | D20: =IF(TRIM(Sheet1!D5)="","",Sheet1!D5) -> NORTH | E20: =IFERROR(IF(TRIM(Sheet1!P5)="","",VALUE(SUBSTITUTE(SUBSTITUTE(Sheet1!P5," bps",""),",",""))),"") -> 35 | F20: =IFERROR(IF(Sheet1!V5="","",N(Sheet1!V5)*100),"") -> 1.96116
A21: =Sheet1!J2 -> Region | B21: 4 | C21: =IFERROR(N(Sheet1!J6)*100,0) -> 14.590385 | D21: =IF(TRIM(Sheet1!D6)="","",Sheet1!D6) -> NORTHEAST | E21: =IFERROR(IF(TRIM(Sheet1!P6)="","",VALUE(SUBSTITUTE(SUBSTITUTE(Sheet1!P6," bps",""),",",""))),"") -> -65 | F21: =IFERROR(IF(Sheet1!V6="","",N(Sheet1!V6)*100),"") -> -6.7040067
A22: =Sheet1!J2 -> Region | B22: 5 | C22: =IFERROR(N(Sheet1!J7)*100,0) -> 5.0811878 | D22: =IF(TRIM(Sheet1!D7)="","",Sheet1!D7) -> SOUTH | E22: =IFERROR(IF(TRIM(Sheet1!P7)="","",VALUE(SUBSTITUTE(SUBSTITUTE(Sheet1!P7," bps",""),",",""))),"") -> -34 | F22: =IFERROR(IF(Sheet1!V7="","",N(Sheet1!V7)*100),"") -> -8.7234582
A23: =Sheet1!K2 -> Packsize | B23: 1 | C23: =IFERROR(N(Sheet1!K3)*100,0) -> 4.2699995 | D23: =IF(TRIM(Sheet1!E3)="","",Sheet1!E3) -> S | E23: =IFERROR(IF(TRIM(Sheet1!Q3)="","",VALUE(SUBSTITUTE(SUBSTITUTE(Sheet1!Q3," bps",""),",",""))),"") -> -87 | F23: =IFERROR(IF(Sheet1!W3="","",N(Sheet1!W3)*100),"") -> -19.016239
A24: =Sheet1!K2 -> Packsize | B24: 2 | C24: =IFERROR(N(Sheet1!K4)*100,0) -> 8.6627068 | D24: =IF(TRIM(Sheet1!E4)="","",Sheet1!E4) -> M | E24: =IFERROR(IF(TRIM(Sheet1!Q4)="","",VALUE(SUBSTITUTE(SUBSTITUTE(Sheet1!Q4," bps",""),",",""))),"") -> -109 | F24: =IFERROR(IF(Sheet1!W4="","",N(Sheet1!W4)*100),"") -> -13.455768
A25: =Sheet1!K2 -> Packsize | B25: 3 | C25: =IFERROR(N(Sheet1!K5)*100,0) -> 14.8535 | D25: =IF(TRIM(Sheet1!E5)="","",Sheet1!E5) -> L | E25: =IFERROR(IF(TRIM(Sheet1!Q5)="","",VALUE(SUBSTITUTE(SUBSTITUTE(Sheet1!Q5," bps",""),",",""))),"") -> 4 | F25: =IFERROR(IF(Sheet1!W5="","",N(Sheet1!W5)*100),"") -> -2.3175949
A26: =Sheet1!K2 -> Packsize | B26: 4 | C26: =IFERROR(N(Sheet1!K6)*100,0) -> 19.869052 | D26: =IF(TRIM(Sheet1!E6)="","",Sheet1!E6) -> XL | E26: =IFERROR(IF(TRIM(Sheet1!Q6)="","",VALUE(SUBSTITUTE(SUBSTITUTE(Sheet1!Q6," bps",""),",",""))),"") -> 195 | F26: =IFERROR(IF(Sheet1!W6="","",N(Sheet1!W6)*100),"") -> 8.063572
A27: =Sheet1!K2 -> Packsize | B27: 5 | C27: =IFERROR(N(Sheet1!K7)*100,0) -> 4.1325837 | D27: =IF(TRIM(Sheet1!E7)="","",Sheet1!E7) -> XXL | E27: =IFERROR(IF(TRIM(Sheet1!Q7)="","",VALUE(SUBSTITUTE(SUBSTITUTE(Sheet1!Q7," bps",""),",",""))),"") -> -47 | F27: =IFERROR(IF(Sheet1!W7="","",N(Sheet1!W7)*100),"") -> -12.505055
A31: LIQUID — Decomposition source (raw shares)
A32: Dimension | B32: Block | C32: Share% | D32: Label | E32: BPS | F32: Growth%
A33: =Sheet1!G9 -> Total TH | B33: 1 | C33: =IFERROR(N(Sheet1!G10)*100,0) -> 39.367265 | D33: =IF(TRIM(Sheet1!A10)="","",Sheet1!A10) -> LIQUID | E33: =IFERROR(IF(TRIM(Sheet1!M10)="","",VALUE(SUBSTITUTE(SUBSTITUTE(Sheet1!M10," bps",""),",",""))),"") -> 242 | F33: =IFERROR(IF(Sheet1!S10="","",N(Sheet1!S10)*100),"") -> 27.503667
A34: =Sheet1!G9 -> Total TH | B34: 2 | C34: =IFERROR(N(Sheet1!G11)*100,0) -> 0 | D34: =IF(TRIM(Sheet1!A11)="","",Sheet1!A11) | E34: =IFERROR(IF(TRIM(Sheet1!M11)="","",VALUE(SUBSTITUTE(SUBSTITUTE(Sheet1!M11," bps",""),",",""))),"") | F34: =IFERROR(IF(Sheet1!S11="","",N(Sheet1!S11)*100),"")
A35: =Sheet1!G9 -> Total TH | B35: 3 | C35: =IFERROR(N(Sheet1!G12)*100,0) -> 0 | D35: =IF(TRIM(Sheet1!A12)="","",Sheet1!A12) | E35: =IFERROR(IF(TRIM(Sheet1!M12)="","",VALUE(SUBSTITUTE(SUBSTITUTE(Sheet1!M12," bps",""),",",""))),"") | F35: =IFERROR(IF(Sheet1!S12="","",N(Sheet1!S12)*100),"")
A36: =Sheet1!G9 -> Total TH | B36: 4 | C36: =IFERROR(N(Sheet1!G13)*100,0) -> 0 | D36: =IF(TRIM(Sheet1!A13)="","",Sheet1!A13) | E36: =IFERROR(IF(TRIM(Sheet1!M13)="","",VALUE(SUBSTITUTE(SUBSTITUTE(Sheet1!M13," bps",""),",",""))),"") | F36: =IFERROR(IF(Sheet1!S13="","",N(Sheet1!S13)*100),"")
A37: =Sheet1!G9 -> Total TH | B37: 5 | C37: =IFERROR(N(Sheet1!G14)*100,0) -> 0 | D37: =IF(TRIM(Sheet1!A14)="","",Sheet1!A14) | E37: =IFERROR(IF(TRIM(Sheet1!M14)="","",VALUE(SUBSTITUTE(SUBSTITUTE(Sheet1!M14," bps",""),",",""))),"") | F37: =IFERROR(IF(Sheet1!S14="","",N(Sheet1!S14)*100),"")
A38: =Sheet1!H9 -> Channel | B38: 1 | C38: =IFERROR(N(Sheet1!H10)*100,0) -> 13.971965 | D38: =IF(TRIM(Sheet1!B10)="","",Sheet1!B10) -> SH CHAIN | E38: =IFERROR(IF(TRIM(Sheet1!N10)="","",VALUE(SUBSTITUTE(SUBSTITUTE(Sheet1!N10," bps",""),",",""))),"") -> -85 | F38: =IFERROR(IF(Sheet1!T10="","",N(Sheet1!T10)*100),"") -> 18.085306
A39: =Sheet1!H9 -> Channel | B39: 2 | C39: =IFERROR(N(Sheet1!H11)*100,0) -> 0.74350914 | D39: =IF(TRIM(Sheet1!B11)="","",Sheet1!B11) -> SH Online | E39: =IFERROR(IF(TRIM(Sheet1!N11)="","",VALUE(SUBSTITUTE(SUBSTITUTE(Sheet1!N11," bps",""),",",""))),"") -> 8 | F39: =IFERROR(IF(Sheet1!T11="","",N(Sheet1!T11)*100),"") -> 40.367161
A40: =Sheet1!H9 -> Channel | B40: 3 | C40: =IFERROR(N(Sheet1!H12)*100,0) -> 4.4699993 | D40: =IF(TRIM(Sheet1!B12)="","",Sheet1!B12) -> OT | E40: =IFERROR(IF(TRIM(Sheet1!N12)="","",VALUE(SUBSTITUTE(SUBSTITUTE(Sheet1!N12," bps",""),",",""))),"") -> -17 | F40: =IFERROR(IF(Sheet1!T12="","",N(Sheet1!T12)*100),"") -> 20.656131
A41: =Sheet1!H9 -> Channel | B41: 4 | C41: =IFERROR(N(Sheet1!H13)*100,0) -> 8.9555564 | D41: =IF(TRIM(Sheet1!B13)="","",Sheet1!B13) -> LMT | E41: =IFERROR(IF(TRIM(Sheet1!N13)="","",VALUE(SUBSTITUTE(SUBSTITUTE(Sheet1!N13," bps",""),",",""))),"") -> 71 | F41: =IFERROR(IF(Sheet1!T13="","",N(Sheet1!T13)*100),"") -> 36.059292
A42: =Sheet1!H9 -> Channel | B42: 5 | C42: =IFERROR(N(Sheet1!H14)*100,0) -> 11.226235 | D42: =IF(TRIM(Sheet1!B14)="","",Sheet1!B14) -> CVS | E42: =IFERROR(IF(TRIM(Sheet1!N14)="","",VALUE(SUBSTITUTE(SUBSTITUTE(Sheet1!N14," bps",""),",",""))),"") -> 266 | F42: =IFERROR(IF(Sheet1!T14="","",N(Sheet1!T14)*100),"") -> 64.194712
A43: =Sheet1!I9 -> Price | B43: 1 | C43: =IFERROR(N(Sheet1!I10)*100,0) -> 2 | D43: =IF(TRIM(Sheet1!C10)="","",Sheet1!C10) -> Tier1 | E43: =IFERROR(IF(TRIM(Sheet1!O10)="","",VALUE(SUBSTITUTE(SUBSTITUTE(Sheet1!O10," bps",""),",",""))),"") -> 139 | F43: =IFERROR(IF(Sheet1!U10="","",N(Sheet1!U10)*100),"") -> 208.37462
...

Sheet SKILL
A1: SKILL: Columnar Marimekko Decomposition Chart
A2: version 2.0.0 | paste-ready reference for colleagues
A4: 1. WORKBOOK PREREQUISITES
A5: Define these in Name Manager, one set per product category. Ranges INCLUDE the header row.
A6: cont_<product> e.g. cont_powder -> Sheet1!$G$2:$K$7 (share proportions)
A7: bps_<product> e.g. bps_powder -> Sheet1!$M$2:$Q$7 (variance in bps, TEXT)
A8: growth_pct_<product> e.g. growth_pct_powder -> Sheet1!$S$2:$W$7 (growth rates)
A9: label_<product> e.g. label_powder -> Sheet1!$A$2:$E$7 (Excel Table)
A10: Layout: 5 dimension columns wide x 5 block rows tall. Products here: powder, liquid, fab_en, dish.
A12: 2. THE THREE RULES THAT DECIDE CORRECTNESS
A13: Each of these caused a visibly wrong chart during development. Read before writing any code.
A15: RULE 1 - DO NOT RENORMALIZE THE SHARES
... A106: dimension headers #0284C7 (blue).

Sheet SKILL_PY
A1: # SKILL - Method A: Python in Excel (=PY)
A2: # Type =PY( in a cell, then paste everything below.
A3: # Requires Python in Excel. #NAME? or #BUSY! means it is unavailable -> use Method B.
A4: # NOT verified in this environment - written to the documented API.
A6: import matplotlib.pyplot as plt
A7: import pandas as pd
A8: import numpy as np
A9: import re
A11: category = "powder" # powder | liquid | fab_en | dish
A13: shares_df = xl(f"cont_{category}", headers=True)
A14: bps_df = xl(f"bps_{category}", headers=True)
A15: growth_df = xl(f"growth_pct_{category}", headers=True)
... A83: fig

Sheet SKILL_JS
A1: // SKILL - Method B: Office.js shapes (no Python required)
A2: // STEP 2 of 3. Run STEP 3 (grouping, at the bottom) separately afterwards.
A3: // Set SRC, PREFIX and TITLE per category, then run once per category.
A5: await Excel.run(async (context) => {
A6: const SHEET = "Decomposition";
A7: const SRC = "A3:F27"; // A33:F57 liquid | A63:F87 fab_en | A93:F117 dish
A8: const PREFIX = "pw"; // lq | fb | dw
A9: const TITLE = "POWDER \u2014 Columnar Marimekko Decomposition";
A10: const X0 = 539, Y0 = 20; // X0 must clear your data columns (in points)
A11: const COL_W = 150, GAP = 0, PLOT_H = 620; // GAP 0 => flush columns
A12: const POS = "#1B8129", NEG = "#D81E3A", NEUTRAL = "#9CA3AF";
A14: const sheet = context.workbook.worksheets.getItem(SHEET);
... A126: });
